### Catch Error in Fetching data
project files in this link   https://stackblitz.com/edit/stackblitz-starters-pnneft?file=index.js  
                            

example code :
```js
const axios = require('axios')
let result = null

axios('https://jsonplaceholder.typicode.com/todos/1').then(response =>{ 
    result = response.data
    console.log('result inside', result)
}).catch((error)=>{
    console.log(' Something wrong happened')
    console.log(error.message)
})

async function dataano() {
    try {
        let response = await axios('https://jsonplaceholder.typicode.com/todos/1')
        let result = response.data
        console.log(result)
          
    } catch (error) {
        console.log("some wrong happend")
        console.log(error.message)
    }
}

dataano()

console.log('result outside', result)

```

### Explaination:

This code demonstrates two ways of error handling in JavaScript using Axios, a popular HTTP client library. Let's break down each part and explain how error handling is done:

1. **Using `.then()` and `.catch()` with Promises:**
   ```js
   const axios = require('axios')
   let result = null

   axios('https://jsonplaceholder.typicode.com/todos/1').then(response =>{ 
       result = response.data
       console.log('result inside', result)
   }).catch((error)=>{
       console.log(' Something wrong happened')
       console.log(error.message)
   })

   console.log('result outside', result)
   ```
   - `axios('https://jsonplaceholder.typicode.com/todos/1')`: This line sends a GET request to the specified URL and returns a Promise.
   - `.then(response => { ... })`: This part executes when the promise is resolved (i.e., the request is successful). It assigns the response data to the `result` variable and logs it.
   - `.catch(error => { ... })`: This part handles any errors that occur during the request. It logs a generic error message and the error's message property (`error.message`).

2. **Using `async/await` with try/catch blocks:**
   ```js
   async function dataano() {
       try {
           let response = await axios('https://jsonplaceholder.typicode.com/todos/1')
           let result = response.data
           console.log(result)
       } catch (error) {
           console.log("some wrong happend")
           console.log(error.message)
       }
   }

   dataano()
   ```
   - `async function dataano() { ... }`: This is an async function that allows the use of `await` inside it to wait for promises to resolve.
   - `try { ... } catch (error) { ... }`: Inside the `dataano` function, we have a try/catch block.
     - `await axios('https://jsonplaceholder.typicode.com/todos/1')`: This line waits for the Axios request to complete. If successful, it assigns the response to `response`.
     - Inside the try block, we log the response data (`result`) if the request is successful.
     - If there's an error during the request, the catch block catches it and logs a custom error message along with the error's message (`error.message`).

In both cases, errors are handled gracefully using either `.catch()` for Promises or `try/catch` for async/await. This ensures that if something goes wrong during the HTTP request, the code can handle it without crashing the program.
